<mujoco model="bimanual_yam_linear">
  <compiler angle="radian" meshdir="assets/"/>

  <option integrator="implicitfast"/>

  <default>
    <default class="left_main">
      <default class="left_yam">
        <joint frictionloss="0.1"/>
        <general biastype="affine" biasprm="0 -1"/>
        <default class="left_dm4340">
          <joint armature="0.032"/>
          <general forcerange="-28 28" gainprm="40" biasprm="0 -40 -2.5"/>
        </default>
        <default class="left_dm4310">
          <joint armature="0.0018"/>
          <general forcerange="-10 10" gainprm="10" biasprm="0 -10 -1"/>
        </default>
        <default class="left_visual">
          <geom type="mesh" contype="0" conaffinity="0" density="0" material="black"/>
        </default>
        <default class="left_collision">
          <geom type="capsule" group="4"/>
          <default class="left_sphere_collision">
            <geom size="0.0006 0 0" type="sphere" rgba="1 0 0 1"/>
          </default>
        </default>
        <default class="left_finger">
          <joint type="slide" armature="0.1"/>
          <general ctrlrange="0 0.1" gainprm="100" biasprm="0 -100 -10"/>
        </default>
      </default>
    </default>
    <default class="right_main">
      <default class="right_yam">
        <joint frictionloss="0.1"/>
        <general biastype="affine" biasprm="0 -1"/>
        <default class="right_dm4340">
          <joint armature="0.032"/>
          <general forcerange="-28 28" gainprm="40" biasprm="0 -40 -2.5"/>
        </default>
        <default class="right_dm4310">
          <joint armature="0.0018"/>
          <general forcerange="-10 10" gainprm="10" biasprm="0 -10 -1"/>
        </default>
        <default class="right_visual">
          <geom type="mesh" contype="0" conaffinity="0" density="0" material="black"/>
        </default>
        <default class="right_collision">
          <geom type="capsule" group="4"/>
          <default class="right_sphere_collision">
            <geom size="0.0006 0 0" type="sphere" rgba="1 0 0 1"/>
          </default>
        </default>
        <default class="right_finger">
          <joint type="slide" armature="0.1"/>
          <general ctrlrange="0 0.1" gainprm="100" biasprm="0 -100 -10"/>
        </default>
      </default>
    </default>
  </default>

  <asset>
    <material name="left_black" rgba="0.25 0.25 0.25 1"/>
    <material name="left_white" rgba="0.9 0.9 0.9 1"/>
    <material name="right_black" rgba="0.25 0.25 0.25 1"/>
    <material name="right_white" rgba="0.9 0.9 0.9 1"/>
    <mesh name="left_model2" content_type="model/obj" file="model2.obj"/>
    <mesh name="left_model2__2" content_type="model/obj" file="model2__2.obj"/>
    <mesh name="left_model2__3" content_type="model/obj" file="model2__3.obj"/>
    <mesh name="left_model2__4" content_type="model/obj" file="model2__4.obj"/>
    <mesh name="left_model2__5" content_type="model/obj" file="model2__5.obj"/>
    <mesh name="left_model2__6" content_type="model/obj" file="model2__6.obj"/>
    <mesh name="left_model2__7" content_type="model/obj" file="model2__7.obj"/>
    <mesh name="left_model2__8" content_type="model/obj" file="model2__8.obj"/>
    <mesh name="left_model2__9" content_type="model/obj" file="model2__9.obj"/>
    <mesh name="left_model2__10" content_type="model/obj" file="model2__10.obj"/>
    <mesh name="left_model2__11" content_type="model/obj" file="model2__11.obj"/>
    <mesh name="left_model2__12" content_type="model/obj" file="model2__12.obj"/>
    <mesh name="left_model2__13" content_type="model/obj" file="model2__13.obj"/>
    <mesh name="left_model2__14" content_type="model/obj" file="model2__14.obj"/>
    <mesh name="left_model2__15" content_type="model/obj" file="model2__15.obj"/>
    <mesh name="left_model2__16" content_type="model/obj" file="model2__16.obj"/>
    <mesh name="left_model2__17" content_type="model/obj" file="model2__17.obj"/>
    <mesh name="left_model_gripper" content_type="model/obj" file="gripper_linear.obj"/>
    <mesh name="left_model_tip_left" content_type="model/obj" file="tip_left_linear.obj"/>
    <mesh name="left_model_tip_right" content_type="model/obj" file="tip_right_linear.obj"/>
    <mesh name="right_model2" file="model2.obj"/>
    <mesh name="right_model2__2" file="model2__2.obj"/>
    <mesh name="right_model2__3" file="model2__3.obj"/>
    <mesh name="right_model2__4" file="model2__4.obj"/>
    <mesh name="right_model2__5" file="model2__5.obj"/>
    <mesh name="right_model2__6" file="model2__6.obj"/>
    <mesh name="right_model2__7" file="model2__7.obj"/>
    <mesh name="right_model2__8" file="model2__8.obj"/>
    <mesh name="right_model2__9" file="model2__9.obj"/>
    <mesh name="right_model2__10" file="model2__10.obj"/>
    <mesh name="right_model2__11" file="model2__11.obj"/>
    <mesh name="right_model2__12" file="model2__12.obj"/>
    <mesh name="right_model2__13" file="model2__13.obj"/>
    <mesh name="right_model2__14" file="model2__14.obj"/>
    <mesh name="right_model2__15" file="model2__15.obj"/>
    <mesh name="right_model2__16" file="model2__16.obj"/>
    <mesh name="right_model2__17" file="model2__17.obj"/>
    <mesh name="right_model_gripper" file="gripper_linear.obj"/>
    <mesh name="right_model_tip_left" file="tip_left_linear.obj"/>
    <mesh name="right_model_tip_right" file="tip_right_linear.obj"/>
  </asset>

  <worldbody>
    <body name="bimanual_base">
      <body name="left_arm" childclass="left_yam" pos="0 0.24 0">
        <geom class="left_visual" pos="0 0 -0.0006" quat="0.707107 0 0 0.707107" material="left_black" mesh="left_model2"/>
        <geom class="left_collision" size="0.033 0.01" pos="0 0 0.026"/>
        <body name="left_link_1" pos="0 0 0.0631" quat="0.707107 0 0 0.707107">
          <inertial pos="-0.00192861 -0.00795735 0.0208176" quat="0.297851 0.642634 0.360045 0.607185" mass="0.12415" diaginertia="0.000180751 0.000145532 5.89179e-05"/>
          <joint name="left_joint1" class="left_dm4340" pos="0 0 0" axis="0 0 1" range="-2.61799 3.05433"/>
          <geom class="left_visual" pos="5.26159e-07 2.34355e-07 -0.0632" quat="1 0 0 0" material="left_black" mesh="left_model2__2"/>
          <body name="left_link_2" pos="2.5e-05 -0.02 0.0409" quat="0.5 0.5 0.5 0.5" gravcomp="1">
            <inertial pos="0.132008 2.10599e-06 0.000293073" quat="0.5 0.5 0.5 0.5" mass="1.24434" diaginertia="0.0121902 0.0121318 0.000683304"/>
            <joint name="left_joint2" class="left_dm4340" pos="0 0 0" axis="0 0 1" range="0 3.66519"/>
            <geom class="left_visual" pos="0.0199992 -0.1041 -2.44738e-05" quat="0.5 -0.5 -0.5 -0.5" material="left_black" mesh="left_model2__3"/>
            <geom class="left_visual" pos="0.0199992 -0.1041 -2.44738e-05" quat="0.5 -0.5 -0.5 -0.5" material="left_black" mesh="left_model2__4"/>
            <geom class="left_visual" pos="0.0199992 -0.1041 -2.44738e-05" quat="0.5 -0.5 -0.5 -0.5" material="left_white" mesh="left_model2__5"/>
            <geom class="left_collision" size="0.032 0.11" pos="0.13 0 0" quat="0.707107 0 0.707107 0"/>
            <geom class="left_collision" size="0.033 0.02"/>
            <geom class="left_collision" size="0.033 0.025" pos="0.265 0 0"/>
            <body name="left_link_3" pos="0.264 0 0" quat="0 1 0 0" gravcomp="1">
              <inertial pos="-0.121816 -0.054846 -0.000111108" quat="0.5 0.5 0.5 0.5" mass="0.853698" diaginertia="0.00699732 0.00696112 0.000788244"/>
              <joint name="left_joint3" class="left_dm4340" pos="0 0 0" axis="0 0 1" range="0 3.66519"/>
              <geom class="left_visual" pos="-0.244001 0.104101 2.44738e-05" quat="0.5 0.5 0.5 -0.5" material="left_black" mesh="left_model2__6"/>
              <geom class="left_visual" pos="-0.244001 0.104101 2.44738e-05" quat="0.5 0.5 0.5 -0.5" material="left_black" mesh="left_model2__7"/>
              <geom class="left_visual" pos="-0.244001 0.104101 2.44738e-05" quat="0.5 0.5 0.5 -0.5" material="left_white" mesh="left_model2__8"/>
              <geom class="left_visual" pos="-0.244001 0.104101 2.44738e-05" quat="0.5 0.5 0.5 -0.5" material="left_black" mesh="left_model2__9"/>
              <geom class="left_collision" size="0.034 0.12" pos="-0.14 -0.06 0" quat="0.707107 0 0.707107 0"/>
              <geom class="left_collision" size="0.034 0.015" pos="-0.24 -0.06 0"/>
              <body name="left_link_4" pos="-0.245 -0.06 0" gravcomp="1">
                <inertial pos="-0.0769778 -0.0527104 0.000154878" quat="0.66661 0.66661 -0.235862 -0.235862" mass="0.463511" diaginertia="0.000791532 0.000744733 0.000282116"/>
                <joint name="left_joint4" class="left_dm4310" pos="0 0 0" axis="0 0 1" range="-1.5708 1.5708"/>
                <geom class="left_visual" pos="0.00100023 0.164101 2.44738e-05" quat="0.5 0.5 0.5 -0.5" material="left_black" mesh="left_model2__10"/>
                <geom class="left_collision" size="0.03 0.015" pos="-0.073 -0.06 0" quat="0.707107 0.707107 0 0"/>
                <body name="left_link_5" pos="-0.074 -0.0395 2.5e-05" quat="0.5 -0.5 0.5 0.5" gravcomp="1">
                  <inertial pos="3.64861e-05 0.00025665 0.0353526" mass="0.350962" diaginertia="0.000197802 0.0001775 0.000147402"/>
                  <joint name="left_joint5" class="left_dm4310" pos="0 0 0" axis="0 0 1" range="-1.5708 1.5708"/>
                  <geom class="left_visual" pos="0 -0.0749971 0.203601" quat="1.32679e-06 1 0 0" material="left_black" mesh="left_model2__11"/>
                  <geom class="left_collision" size="0.03 0.015" pos="0 0.025 0.0395" quat="0.707107 0.707107 0 0"/>
                  <body name="left_link_6" pos="0 0.0353 0.0395" quat="0.707107 -0.707107 0 0" gravcomp="1">
                    <joint name="left_joint6" class="left_dm4310" pos="0 0 0" axis="0 0 -1" range="-2.0944 2.0944"/>
                    <geom name="left_link6_visual" class="left_visual" pos="0 0 0.027" quat="0 0.707107 -0.707107 0" material="left_black" mesh="left_model_gripper"/>
                    <geom class="left_collision" size="0.01 0.035" pos="0 0.026 0.052" quat="0.707107 0 0.707107 0"/>
                    <geom class="left_collision" size="0.03 0.005" pos="0 0 0.03" quat="0.707107 0 0 0.707107"/>
                    <geom class="left_collision" size="0.01 0.035" pos="0 -0.026 0.052" quat="0.707107 0 0.707107 0"/>
                    <site name="left_tcp_site" pos="0 0 0" quat="0.707107 0 0 -0.707107" group="4" rgba="1 0 0 1"/>
                    <site name="left_grasp_site" pos="0 0 0.1347" quat="0.707107 0 0 -0.707107" group="4" rgba="0 1 0 1"/>
                    <body name="left_link_left_finger" pos="-0.037 0.0392 0.0605" quat="0.707107 0 0.707107 0" gravcomp="1">
                      <joint name="left_left_finger" class="left_finger" pos="0 0 0" axis="0 0 1" range="-0.0485 0"/>
                      <geom name="left_left_tip_visual" class="left_visual" pos="-0.03992 -0.0392 0.049" quat="0.5 0.5 0.5 0.5" material="left_black" mesh="left_model_tip_left"/>
                      <geom name="left_left_tip_collider_0" class="left_collision" size="0.0068 0.03 0.002" pos="-0.021 -0.04 0.0331" type="box"/>
                      <geom name="left_left_tip_collider_1" class="left_collision" size="0.0048 0.034 0.002" pos="-0.051 -0.025 0.0331" quat="0.561168 0 0 0.827702" type="box"/>
                      <geom name="left_left_tip_collider_2" class="left_collision" size="0.0048 0.034 0.002" pos="-0.051 -0.055 0.0331" quat="0.825336 0 0 0.564642" type="box"/>
                    </body>
                    <body name="left_link_right_finger" pos="0.037 -0.0392 0.0605" quat="0.707107 0 0.707107 0" gravcomp="1">
                      <joint name="left_right_finger" class="left_finger" pos="0 0 0" axis="0 0 -1" range="-0.0485 0"/>
                      <geom name="left_right_tip_visual" class="left_visual" pos="-0.03992 0.0392 -0.049" quat="0.5 0.5 0.5 0.5" material="left_black" mesh="left_model_tip_right"/>
                      <geom name="left_right_tip_collider_0" class="left_collision" size="0.0068 0.03 0.002" pos="-0.021 0.04 -0.0331" type="box"/>
                      <geom name="left_right_tip_collider_1" class="left_collision" size="0.0048 0.034 0.002" pos="-0.051 0.025 -0.0331" quat="0.561168 0 0 -0.827702" type="box"/>
                      <geom name="left_right_tip_collider_2" class="left_collision" size="0.0048 0.034 0.002" pos="-0.051 0.055 -0.0331" quat="0.825336 0 0 -0.564642" type="box"/>
                    </body>
                  </body>
                </body>
              </body>
            </body>
          </body>
        </body>
      </body>
      <body name="right_arm" childclass="right_yam" pos="0 -0.24 0">
        <geom class="right_visual" pos="0 0 -0.0006" quat="0.707107 0 0 0.707107" material="right_black" mesh="right_model2"/>
        <geom class="right_collision" size="0.033 0.01" pos="0 0 0.026"/>
        <body name="right_link_1" pos="0 0 0.0631" quat="0.707107 0 0 0.707107">
          <inertial pos="-0.00192861 -0.00795735 0.0208176" quat="0.297851 0.642634 0.360045 0.607185" mass="0.12415" diaginertia="0.000180751 0.000145532 5.89179e-05"/>
          <joint name="right_joint1" class="right_dm4340" pos="0 0 0" axis="0 0 1" range="-2.61799 3.05433"/>
          <geom class="right_visual" pos="5.26159e-07 2.34355e-07 -0.0632" quat="1 0 0 0" material="right_black" mesh="right_model2__2"/>
          <body name="right_link_2" pos="2.5e-05 -0.02 0.0409" quat="0.5 0.5 0.5 0.5" gravcomp="1">
            <inertial pos="0.132008 2.10599e-06 0.000293073" quat="0.5 0.5 0.5 0.5" mass="1.24434" diaginertia="0.0121902 0.0121318 0.000683304"/>
            <joint name="right_joint2" class="right_dm4340" pos="0 0 0" axis="0 0 1" range="0 3.66519"/>
            <geom class="right_visual" pos="0.0199992 -0.1041 -2.44738e-05" quat="0.5 -0.5 -0.5 -0.5" material="right_black" mesh="right_model2__3"/>
            <geom class="right_visual" pos="0.0199992 -0.1041 -2.44738e-05" quat="0.5 -0.5 -0.5 -0.5" material="right_black" mesh="right_model2__4"/>
            <geom class="right_visual" pos="0.0199992 -0.1041 -2.44738e-05" quat="0.5 -0.5 -0.5 -0.5" material="right_white" mesh="right_model2__5"/>
            <geom class="right_collision" size="0.032 0.11" pos="0.13 0 0" quat="0.707107 0 0.707107 0"/>
            <geom class="right_collision" size="0.033 0.02"/>
            <geom class="right_collision" size="0.033 0.025" pos="0.265 0 0"/>
            <body name="right_link_3" pos="0.264 0 0" quat="0 1 0 0" gravcomp="1">
              <inertial pos="-0.121816 -0.054846 -0.000111108" quat="0.5 0.5 0.5 0.5" mass="0.853698" diaginertia="0.00699732 0.00696112 0.000788244"/>
              <joint name="right_joint3" class="right_dm4340" pos="0 0 0" axis="0 0 1" range="0 3.66519"/>
              <geom class="right_visual" pos="-0.244001 0.104101 2.44738e-05" quat="0.5 0.5 0.5 -0.5" material="right_black" mesh="right_model2__6"/>
              <geom class="right_visual" pos="-0.244001 0.104101 2.44738e-05" quat="0.5 0.5 0.5 -0.5" material="right_black" mesh="right_model2__7"/>
              <geom class="right_visual" pos="-0.244001 0.104101 2.44738e-05" quat="0.5 0.5 0.5 -0.5" material="right_white" mesh="right_model2__8"/>
              <geom class="right_visual" pos="-0.244001 0.104101 2.44738e-05" quat="0.5 0.5 0.5 -0.5" material="right_black" mesh="right_model2__9"/>
              <geom class="right_collision" size="0.034 0.12" pos="-0.14 -0.06 0" quat="0.707107 0 0.707107 0"/>
              <geom class="right_collision" size="0.034 0.015" pos="-0.24 -0.06 0"/>
              <body name="right_link_4" pos="-0.245 -0.06 0" gravcomp="1">
                <inertial pos="-0.0769778 -0.0527104 0.000154878" quat="0.66661 0.66661 -0.235862 -0.235862" mass="0.463511" diaginertia="0.000791532 0.000744733 0.000282116"/>
                <joint name="right_joint4" class="right_dm4310" pos="0 0 0" axis="0 0 1" range="-1.5708 1.5708"/>
                <geom class="right_visual" pos="0.00100023 0.164101 2.44738e-05" quat="0.5 0.5 0.5 -0.5" material="right_black" mesh="right_model2__10"/>
                <geom class="right_collision" size="0.03 0.015" pos="-0.073 -0.06 0" quat="0.707107 0.707107 0 0"/>
                <body name="right_link_5" pos="-0.074 -0.0395 2.5e-05" quat="0.5 -0.5 0.5 0.5" gravcomp="1">
                  <inertial pos="3.64861e-05 0.00025665 0.0353526" mass="0.350962" diaginertia="0.000197802 0.0001775 0.000147402"/>
                  <joint name="right_joint5" class="right_dm4310" pos="0 0 0" axis="0 0 1" range="-1.5708 1.5708"/>
                  <geom class="right_visual" pos="0 -0.0749971 0.203601" quat="1.32679e-06 1 0 0" material="right_black" mesh="right_model2__11"/>
                  <geom class="right_collision" size="0.03 0.015" pos="0 0.025 0.0395" quat="0.707107 0.707107 0 0"/>
                  <body name="right_link_6" pos="0 0.0353 0.0395" quat="0.707107 -0.707107 0 0" gravcomp="1">
                    <joint name="right_joint6" class="right_dm4310" pos="0 0 0" axis="0 0 -1" range="-2.0944 2.0944"/>
                    <geom name="right_link6_visual" class="right_visual" pos="0 0 0.027" quat="0 0.707107 -0.707107 0" material="right_black" mesh="right_model_gripper"/>
                    <geom class="right_collision" size="0.01 0.035" pos="0 0.026 0.052" quat="0.707107 0 0.707107 0"/>
                    <geom class="right_collision" size="0.03 0.005" pos="0 0 0.03" quat="0.707107 0 0 0.707107"/>
                    <geom class="right_collision" size="0.01 0.035" pos="0 -0.026 0.052" quat="0.707107 0 0.707107 0"/>
                    <site name="right_tcp_site" pos="0 0 0" quat="0.707107 0 0 -0.707107" group="4" rgba="1 0 0 1"/>
                    <site name="right_grasp_site" pos="0 0 0.1347" quat="0.707107 0 0 -0.707107" group="4" rgba="0 1 0 1"/>
                    <body name="right_link_left_finger" pos="-0.037 0.0392 0.0605" quat="0.707107 0 0.707107 0" gravcomp="1">
                      <joint name="right_left_finger" class="right_finger" pos="0 0 0" axis="0 0 1" range="-0.0485 0"/>
                      <geom name="right_left_tip_visual" class="right_visual" pos="-0.03992 -0.0392 0.049" quat="0.5 0.5 0.5 0.5" material="right_black" mesh="right_model_tip_left"/>
                      <geom name="right_left_tip_collider_0" class="right_collision" size="0.0068 0.03 0.002" pos="-0.021 -0.04 0.0331" type="box"/>
                      <geom name="right_left_tip_collider_1" class="right_collision" size="0.0048 0.034 0.002" pos="-0.051 -0.025 0.0331" quat="0.561168 0 0 0.827702" type="box"/>
                      <geom name="right_left_tip_collider_2" class="right_collision" size="0.0048 0.034 0.002" pos="-0.051 -0.055 0.0331" quat="0.825336 0 0 0.564642" type="box"/>
                    </body>
                    <body name="right_link_right_finger" pos="0.037 -0.0392 0.0605" quat="0.707107 0 0.707107 0" gravcomp="1">
                      <joint name="right_right_finger" class="right_finger" pos="0 0 0" axis="0 0 -1" range="-0.0485 0"/>
                      <geom name="right_right_tip_visual" class="right_visual" pos="-0.03992 0.0392 -0.049" quat="0.5 0.5 0.5 0.5" material="right_black" mesh="right_model_tip_right"/>
                      <geom name="right_right_tip_collider_0" class="right_collision" size="0.0068 0.03 0.002" pos="-0.021 0.04 -0.0331" type="box"/>
                      <geom name="right_right_tip_collider_1" class="right_collision" size="0.0048 0.034 0.002" pos="-0.051 0.025 -0.0331" quat="0.561168 0 0 -0.827702" type="box"/>
                      <geom name="right_right_tip_collider_2" class="right_collision" size="0.0048 0.034 0.002" pos="-0.051 0.055 -0.0331" quat="0.825336 0 0 -0.564642" type="box"/>
                    </body>
                  </body>
                </body>
              </body>
            </body>
          </body>
        </body>
      </body>
    </body>
  </worldbody>

  <actuator>
    <general name="left_joint1" class="left_dm4340" joint="left_joint1" ctrlrange="-2.61799 3.05433"/>
    <general name="left_joint2" class="left_dm4340" joint="left_joint2" ctrlrange="0 3.66519"/>
    <general name="left_joint3" class="left_dm4340" joint="left_joint3" ctrlrange="0 3.66519"/>
    <general name="left_joint4" class="left_dm4310" joint="left_joint4" ctrlrange="-1.5708 1.5708" gainprm="20" biasprm="0 -20 -0.5"/>
    <general name="left_joint5" class="left_dm4310" joint="left_joint5" ctrlrange="-1.5708 1.5708"/>
    <general name="left_joint6" class="left_dm4310" joint="left_joint6" ctrlrange="-2.0944 2.0944"/>
    <general name="left_gripper_left_tip" class="left_finger" joint="left_left_finger" ctrlrange="-0.0475 0"/>
    <general name="left_gripper_right_tip" class="left_finger" joint="left_right_finger" ctrlrange="-0.0475 0"/>
    <general name="right_joint1" class="right_dm4340" joint="right_joint1" ctrlrange="-2.61799 3.05433"/>
    <general name="right_joint2" class="right_dm4340" joint="right_joint2" ctrlrange="0 3.66519"/>
    <general name="right_joint3" class="right_dm4340" joint="right_joint3" ctrlrange="0 3.66519"/>
    <general name="right_joint4" class="right_dm4310" joint="right_joint4" ctrlrange="-1.5708 1.5708" gainprm="20" biasprm="0 -20 -0.5"/>
    <general name="right_joint5" class="right_dm4310" joint="right_joint5" ctrlrange="-1.5708 1.5708"/>
    <general name="right_joint6" class="right_dm4310" joint="right_joint6" ctrlrange="-2.0944 2.0944"/>
    <general name="right_gripper_left_tip" class="right_finger" joint="right_left_finger" ctrlrange="-0.0475 0"/>
    <general name="right_gripper_right_tip" class="right_finger" joint="right_right_finger" ctrlrange="-0.0475 0"/>
  </actuator>
</mujoco>
